Workbook

Sheet 22.3.26
A1: S No. | B1: Description by 5 | D1: gms | E1: carat | F1: @ | I1: Image
A4: 1 | B4: Emd Cab & Dia Earrings (14.5 KT) | C4: Gr Wt | D4: 16.18 | G4: 85000 | I4: #VALUE!
C5: Dia | E5: 3.34
C6: Emd | E6: 30.1
C7: Net Wt | D7: =D4-((E5+E6)/5) -> 9.492
A9: 2 | B9: ruby pear earring yellow gold (14.5KT) | C9: Gr Wt | D9: 3.25 | G9: 33000 | I9: #VALUE!
C10: Dia | E10: 0.26
C11: ruby | E11: 3.34
C12: Net Wt | D12: =D9-((E10+E11)/5) -> 2.53
A14: 3 | B14: snowflake dia earring white gold (14.5KT) | C14: Gr Wt | D14: 6.314 | G14: 47000 | I14: #VALUE!
C15: Dia | E15: 2.28
C16: Net Wt | D16: =D14-((E15)/5) -> 5.858
A18: 4 | B18: dia bracelet white gold (14.5KT) | C18: Gr Wt | D18: 13.191 | G18: 98000 | I18: #VALUE!
C19: Dia | E19: 6.69
C20: Net Wt | D20: =D18-((E19)/5) -> 11.853
A23: 5 | B23: Fancy Yellow Earring Pair 18Kt | C23: Gr Wt | D23: 6.658 | G23: 47000 | I23: #VALUE!
C24: Dia 2pcs | E24: 1.5
C25: Dia 30pcs | E25: 0.5
C26: Net Wt | D26: =D23-((E24+E25)/5) -> 6.258
A29: 6 | B29: Dia Ov + Oct Earrings 14kt WG | C29: Gr Wt | D29: 1.768 | G29: 13001 | I29: #VALUE!
C30: Dia | E30: 0.82
C31: Net Wt | D31: =D29-(E30/5) -> 1.604
A35: 7 | B35: yellow dia + cushion emerald earrings (14.5KT) | C35: Gr Wt | D35: 8.402
C36: Dia | E36: 1.91
C37: y.dia | E37: 1.53
C38: Emd | E38: 3.91
C39: Net Wt | D39: =D35-(E36+E37+E38)/5 -> 6.932
A48: 8 | B48: Emd Half Moon Carving Earring 2Pc Set (14KT) | C48: Gr Wt | D48: 6.35 | G48: 17000 | I48: #VALUE!
C49: Dia | E49: 0.17
C50: Polki | E50: 0.21
C51: Emd | E51: 16.01
C52: Net Wt | D52: =D48-((SUM(E49:E51)/5)) -> 3.072
A57: 11 | B57: Princess Diamond Bracelet - Rose Gold (14.5Kt) | C57: Gr Wt | D57: 10.427 | G57: 70000 | H57: #VALUE!
C58: Dia | E58: 6.02
C59: Net Wt | D59: =D57-((E58/5)) -> 9.223
A61: 13 | B61: Single Emd Pendant (14.5KT) | C61: Gr Wt | D61: 3.736 | G61: 35000 | I61: #VALUE!
C62: Dia | E62: 1.3
C63: Emd | E63: 2.87
C64: Net Wt | D64: =D61-(E62+E63)/5 -> 2.902
A71: 14 | B71: Emd Set 1 14kt | C71: Gr Wt | D71: 47.083 | G71: 332000 | I71: #VALUE!
...

Sheet latest price
C1: date
A2: MTL 24K (10g) | B2: 160000 | C2: 18.03.26
A3: wastage | B3: 1.15
A5: To fill compulsory
A6: If required
A8: S No. | B8: Description by 5 | C8: Date of MFG | D8: Grading | F8: Gross WT | G8: Net WT | H8: CTS | I8: @ | J8: Total | L8: market C.P | M8: home C.P | N8: SP for market | Q8: Image
A11: 1 | B11: Emd Cab & Dia Earrings (14.5 KT) | D11: 14.5 | E11: MTL | F11: 16.18 | G11: =(F11-((H12+H13)/5)) -> 9.492 | H11: - | I11: =(($B$2/(10*24))*D11) -> 9666.6667 | J11: =G11*$B$3*I11 -> 105519.4 | K11: =SUM(J11, J12, (J13), F14) -> 342519.4 | L11: =SUM(J11, J12,J13, F14, F15) -> 352794.98 | M11: =SUM(J11, J12,(J13*0.5), F14, F15) -> 277544.98 | N11: =((SUM(J11, J12, F14, F15)*1.4)+J13) -> 433712.97 | Q11: #VALUE!
E12: dia | F12: - | G12: - | H12: 3.34 | I12: 25000 | J12: =H12*I12 -> 83500
E13: emerald | H13: 30.1 | I13: 5000 | J13: =H13*I13 -> 150500
E14: labour | F14: 3000
E15: tk commission | F15: =K11*VLOOKUP(K11, 'rates tk'!$B$5:$C$10, 2, TRUE) -> 10275.582
A17: 2 | B17: ruby pear earring yellow gold | C17: 31.10.25 | D17: 14.5 | E17: MTL | F17: 3.25 | G17: =(F17-((H18+H19)/5)) -> 2.53 | H17: - | I17: =(($B$2/(10*24))*D17) -> 9666.6667 | J17: =G17*$B$3*I17 -> 28125.167 | K17: =SUM(J17:J19, F20) -> 109625.17 | L17: =SUM(J17, J18, J19, F20, F21) -> 116202.68 | N17: =L17*1.4 -> 162683.75 | Q17: #VALUE!
E18: ruby | F18: - | G18: - | H18: 3.34 | I18: 20000 | J18: =H18*I18 -> 66800
E19: dia rd | F19: - | G19: - | H19: 0.26 | I19: 45000 | J19: =H19*I19 -> 11700
E20: labour | F20: 3000
E21: tk commission | F21: =K17*VLOOKUP(K17, 'rates tk'!$B$5:$C$10, 2, TRUE) -> 6577.51
A24: 3 | B24: snowflake dia earring white gold | C24: 31.10.25 | D24: 14.5 | E24: MTL | F24: 6.314 | G24: =(F24-((H25+H26+H27)/5)) -> 5.858 | H24: - | I24: =(($B$2/(10*24))*D24) -> 9666.6667 | J24: =G24*$B$3*I24 -> 65121.433 | K24: =SUM(J24:J27, F28) -> 160611.43 | L24: =SUM(J24, J25, J26, J27, F28, F29)/5 -> 33407.178 | N24: =L24*1.4 -> 46770.049 | Q24: #VALUE!
E25: dia rd center 2 pc | F25: - | G25: - | H25: 0.55 | I25: 55000 | J25: =H25*I25 -> 30250
E26: dia rd small 12 pcs | F26: - | G26: - | H26: 0.67 | I26: 22000 | J26: =H26*I26 -> 14740
E27: dia rd medium 12 pcs | F27: - | G27: - | H27: 1.06 | I27: 45000 | J27: =H27*I27 -> 47700
E28: labour | F28: 2800
E29: tk commission | F29: =K24*VLOOKUP(K24, 'rates tk'!$B$5:$C$10, 2, TRUE) -> 6424.4573
A32: 5 | B32: Fancy Yellow Earring Pair | D32: 18.5 | E32: MTL | F32: 6.658 | G32: =(F32-((H33+H34)/5)) -> 6.258 | H32: - | I32: =(($B$2/(10*24))*D32) -> 12333.333 | J32: =G32*$B$3*I32 -> 88759.3 | K32: =SUM(J32:J34, F35) -> 164759.3 | L32: =SUM(J32, J33,J34, F35, F36)/5 -> 34269.934 | N32: =L32*1.4 -> 47977.908 | Q32: #VALUE!
E33: dia 2pc | F33: - | G33: - | H33: 1.5 | I33: 42000 | J33: =H33*I33 -> 63000
E34: dia 30pcs | F34: - | G34: - | H34: 0.5 | I34: 18000 | J34: =H34*I34 -> 9000
E35: labour | F35: 4000
E36: tk commission | F36: =K32*VLOOKUP(K32, 'rates tk'!$B$5:$C$10, 2, TRUE) -> 6590.372
A39: 6 | B39: Dia Ov + Oct Earrings WG | D39: 14.5 | E39: MTL | F39: 1.768 | G39: =(F39-(H40/5)) -> 1.604 | H39: - | I39: =(($B$2/(10*24))*D39) -> 9666.6667 | J39: =G39*$B$3*I39 -> 17831.133 | K39: =SUM(J39, J40, F41) -> 44431.133 | L39: =SUM(J39, J40, F41, F42)/5 -> 9597.1248 | N39: =L39*1.4 -> 13435.975 | Q39: #VALUE!
E40: dia | F40: - | G40: - | H40: 0.82 | I40: 30000 | J40: =H40*I40 -> 24600
E41: labour | F41: 2000
E42: tk commission | F42: =K39*VLOOKUP(K39, 'rates tk'!$B$5:$C$10, 2, TRUE) -> 3554.4907
A44: 7 | B44: yellow dia + cushion emerald earrings | D44: 14.5 | E44: MTL | F44: 8.402 | G44: =(F44-((H46+H48+H45+H47)/5)) -> 6.932 | H44: - | I44: =(($B$2/(10*24))*D44) -> 9666.6667 | J44: =G44*$B$3*I44 -> 77060.733 | K44: =SUM(J44, J45, J46, J47, (J48), F49) -> 273691.73 | L44: =SUM(J44, J46,J48, F49, F50, J45, J47)/5 -> 56927.881 | M44: =SUM(J44, J46,(J48*0.5), F49, F50, J45, J47)/5 -> 47973.981 | N44: =((SUM(J44:J47, F49, F50)*1.4)+J48)/5 -> 72535.913 | Q44: #VALUE!
E45: yellow dia | H45: 1.53 | I45: 40000 | J45: =H45*I45 -> 61200
E46: dia +3 | F46: - | G46: - | H46: 0.16 | I46: 21200 | J46: =H46*I46 -> 3392
E47: dia 2.4mm | H47: 1.75 | I47: 22000 | J47: =H47*I47 -> 38500
E48: emerald | H48: 3.91 | I48: 22900 | J48: =H48*I48 -> 89539
E49: labour | F49: 4000
E50: tk commission | F50: =K44*VLOOKUP(K44, 'rates tk'!$B$5:$C$10, 2, TRUE) -> 10947.669
A53: 8 | B53: Emd Half Moon Carving Earring 2Pc Set | D53: 14.5 | E53: MTL | F53: 6.35 | G53: =(F53-((H54+H55+H56)/5)) -> 3.072 | H53: - | I53: =(($B$2/(10*24))*D53) -> 9666.6667 | J53: =G53*$B$3*I53 -> 34150.4 | K53: =SUM(J53, J54, (J55), J56, F57) -> 64540.4 | L53: =SUM(J53, J54, J55, J56, F57, F58)/5 -> 13682.565 | M53: =SUM(J53, J54, (J55*0.5), J56, F57, F58)/5 -> 11281.065 | N53: =((SUM(J53, J54, J56, F57, F58)*1.4)+J55)/5 -> 17234.391 | Q53: #VALUE!
E54: dia | F54: - | G54: - | H54: 0.17 | I54: 18000 | J54: =H54*I54 -> 3060
...

Sheet VM Personal
B2: 122000
B3: 1.15
F5: g.wt | G5: n.wt | H5: cts | I5: @ | J5: total | K5: home cost
A7: 1 | B7: button yellow gold | C7: 31.10.25 | D7: 14.5 | E7: MTL | F7: 29 | G7: =(F7-((H8)/5)) -> 27.588 | H7: - | I7: =(($B$2/(10*24))*D7) -> 7370.8333 | J7: =G7*$B$3*I7 -> 233848.53 | K7: =SUM(J7, J8, F9, F10) -> 528388.53
E8: yellow dia cushion | F8: - | G8: - | H8: 7.06 | I8: 39000 | J8: =H8*I8 -> 275340
E9: labour | F9: 8200
E10: tk commission | F10: 11000
A13: 2 | B13: wii emerald ring | C13: 31.10.25 | D13: 14.5 | E13: MTL | F13: 8.44 | G13: =(F13-((H14+H15)/5)) -> 5.788 | H13: - | I13: =(($B$2/(10*24))*D13) -> 7370.8333 | J13: =G13*$B$3*I13 -> 49061.741 | K13: =SUM(J13, J14, J15, F16, F17) -> 559269.24
E14: yellow dia heart | F14: - | G14: - | H14: 3.71 | I14: 43250 | J14: =H14*I14 -> 160457.5
E15: emerald | H15: 9.55 | I15: 35000 | J15: =H15*I15 -> 334250
E16: labour | F16: 4500
E17: tk commission | F17: 11000
A20: 3 | B20: yellow dia earring | C20: 31.10.25 | D20: 14.5 | E20: MTL | F20: 11.39 | G20: =(F20-((H21)/5)) -> 10.378 | H20: - | I20: 7370.8333 | J20: =G20*$B$3*I20 -> 87968.685 | K20: =SUM(J20, J21, F22, F23) -> 297308.68
E21: yellow dia cushion | F21: - | G21: - | H21: 5.06 | I21: 39000 | J21: =H21*I21 -> 197340
E22: labour | F22: 4000
E23: tk commission | F23: 8000
A26: 4 | B26: dia stud earring oct | C26: 31.10.25 | D26: 14.5 | E26: MTL | F26: 4.802 | G26: =(F26-((H27)/5)) -> 4.362 | H26: - | I26: 7370.8333 | J26: =G26*$B$3*I26 -> 36974.311 | K26: =SUM(J26, J27, F28, F29) -> 308174.31
E27: dia | F27: - | G27: - | H27: 2.2 | I27: 120000 | J27: =H27*I27 -> 264000
E28: labour | F28: 2100
E29: tk commission | F29: 5100
A32: 2 | B32: dia stud eme earring | C32: 31.10.25 | D32: 14.5 | E32: MTL | F32: 4.802 | G32: =(F32-((H33+H34)/5)) -> 4 | H32: - | I32: =(($B$2/(10*24))*D32) -> 7370.8333 | J32: =G32*$B$3*I32 -> 33905.833 | K32: =SUM(J32, J33, J34, F35, F36) -> 112225.83
E33: dia | F33: - | G33: - | H33: 0.46 | I33: 21000 | J33: =H33*I33 -> 9660
E34: emerald | H34: 3.55 | I34: 17200 | J34: =H34*I34 -> 61060
E35: labour | F35: 2500
E36: tk commission | F36: 5100

Sheet sample calc
B2: Legend
B3: compulsory to fill
B4: optional to fill
A6: metal rate | B6: KARAT | C6: @
B7: 24 | C7: 10200
A10: Calculator
A11: metal Karat | B11: 14.5
B13: gm | C13: wastage | D13: ct | E13: @ | F13: Total
A14: net metal | B14: 0.36 | C14: 1.15 | E14: =((C7/B7)*B11) -> 6162.5 | F14: =B14*C14*E14 -> 2551.275
A15: other gemstone
A16: emd | D16: 0.12 | E16: 10000 | F16: =D16*E16 -> 1200
A17: dia | D17: 1.46 | E17: 22000 | F17: =D17*E17 -> 32120
A18: dak
A19: polki
A20: labour | F20: 5200
A22: total before tk comm | F22: =SUM(F14:F20) -> 41071.275
A24: commision T.k | F24: =IF(F22<25000,F22*0.1,IF(F22<50000,F22*0.08,IF(F22<300000,F22*0.06,IF(F22<500000,F22*0.03,IF(F22>500000,F22*0.02,0))))) -> 3285.702
E25: Our cost | F25: =SUM(F22+F24) -> 44356.977
E27: Selling price | F27: =((F25-F16)*1.4)+F16 -> 61619.768

Sheet NFS
A2: 4 | B2: Ruby Set Earrings only | C2: Gr Wt | D2: 10.504 | F2: 48200
C3: Dia | E3: 1.52
B4: NFS | C4: Ruby | E4: 12.55
C5: Net Wt | D5: =D2-(E3+E4)/5 -> 7.69

Sheet rates tk
B3: rates TK
B4: range | C4: percentage
B5: 0 | C5: 0.1
B6: 25000 | C6: 0.08
B7: 50000 | C7: 0.06
B8: 150000 | C8: 0.04
B9: 300000 | C9: 0.03
B10: 500000 | C10: 0.02
